[2022-02-25 01:50:02,991] {taskinstance.py:1032} INFO - Dependencies all met for <TaskInstance: Project_Mapping.load_to_s3 scheduled__2022-02-25T00:00:00+00:00 [queued]>
[2022-02-25 01:50:03,061] {taskinstance.py:1032} INFO - Dependencies all met for <TaskInstance: Project_Mapping.load_to_s3 scheduled__2022-02-25T00:00:00+00:00 [queued]>
[2022-02-25 01:50:03,065] {taskinstance.py:1238} INFO - 
--------------------------------------------------------------------------------
[2022-02-25 01:50:03,068] {taskinstance.py:1239} INFO - Starting attempt 1 of 1
[2022-02-25 01:50:03,071] {taskinstance.py:1240} INFO - 
--------------------------------------------------------------------------------
[2022-02-25 01:50:03,136] {taskinstance.py:1259} INFO - Executing <Task(PythonOperator): load_to_s3> on 2022-02-25 00:00:00+00:00
[2022-02-25 01:50:03,147] {standard_task_runner.py:52} INFO - Started process 3255 to run task
[2022-02-25 01:50:03,160] {standard_task_runner.py:76} INFO - Running: ['***', 'tasks', 'run', 'Project_Mapping', 'load_to_s3', 'scheduled__2022-02-25T00:00:00+00:00', '--job-id', '61', '--raw', '--subdir', 'DAGS_FOLDER/mydag.py', '--cfg-path', '/tmp/tmpxhojl42i', '--error-file', '/tmp/tmpwn8ngyma']
[2022-02-25 01:50:03,165] {standard_task_runner.py:77} INFO - Job 61: Subtask load_to_s3
[2022-02-25 01:50:03,412] {logging_mixin.py:109} INFO - Running <TaskInstance: Project_Mapping.load_to_s3 scheduled__2022-02-25T00:00:00+00:00 [running]> on host 717d92cd82bb
[2022-02-25 01:50:03,736] {taskinstance.py:1426} INFO - Exporting the following env vars:
AIRFLOW_CTX_DAG_OWNER=***
AIRFLOW_CTX_DAG_ID=Project_Mapping
AIRFLOW_CTX_TASK_ID=load_to_s3
AIRFLOW_CTX_EXECUTION_DATE=2022-02-25T00:00:00+00:00
AIRFLOW_CTX_DAG_RUN_ID=scheduled__2022-02-25T00:00:00+00:00
[2022-02-25 01:50:46,231] {logging_mixin.py:109} INFO - Negative
[2022-02-25 01:50:48,084] {logging_mixin.py:109} INFO - reddit_posts_2022-02-25.xlsx
[2022-02-25 01:50:48,089] {taskinstance.py:1700} ERROR - Task failed with exception
Traceback (most recent call last):
  File "/home/airflow/.local/lib/python3.7/site-packages/airflow/models/taskinstance.py", line 1329, in _run_raw_task
    self._execute_task_with_callbacks(context)
  File "/home/airflow/.local/lib/python3.7/site-packages/airflow/models/taskinstance.py", line 1455, in _execute_task_with_callbacks
    result = self._execute_task(context, self.task)
  File "/home/airflow/.local/lib/python3.7/site-packages/airflow/models/taskinstance.py", line 1511, in _execute_task
    result = execute_callable(context=context)
  File "/home/airflow/.local/lib/python3.7/site-packages/airflow/operators/python.py", line 174, in execute
    return_value = self.execute_callable()
  File "/home/airflow/.local/lib/python3.7/site-packages/airflow/operators/python.py", line 185, in execute_callable
    return self.python_callable(*self.op_args, **self.op_kwargs)
  File "/opt/airflow/dags/mydag.py", line 87, in _load_to_s3
    import reddit_data as reddit
  File "/opt/airflow/dags/reddit_data.py", line 9, in <module>
    import s3 as s3boto
  File "/opt/airflow/dags/s3.py", line 44, in <module>
    os.remove(filename)
FileNotFoundError: [Errno 2] No such file or directory: 'reddit_posts_2022-02-25.xlsx'
[2022-02-25 01:50:48,160] {taskinstance.py:1277} INFO - Marking task as FAILED. dag_id=Project_Mapping, task_id=load_to_s3, execution_date=20220225T000000, start_date=20220225T015002, end_date=20220225T015048
[2022-02-25 01:50:48,310] {standard_task_runner.py:92} ERROR - Failed to execute job 61 for task load_to_s3
Traceback (most recent call last):
  File "/home/airflow/.local/lib/python3.7/site-packages/airflow/task/task_runner/standard_task_runner.py", line 85, in _start_by_fork
    args.func(args, dag=self.dag)
  File "/home/airflow/.local/lib/python3.7/site-packages/airflow/cli/cli_parser.py", line 48, in command
    return func(*args, **kwargs)
  File "/home/airflow/.local/lib/python3.7/site-packages/airflow/utils/cli.py", line 92, in wrapper
    return f(*args, **kwargs)
  File "/home/airflow/.local/lib/python3.7/site-packages/airflow/cli/commands/task_command.py", line 298, in task_run
    _run_task_by_selected_method(args, dag, ti)
  File "/home/airflow/.local/lib/python3.7/site-packages/airflow/cli/commands/task_command.py", line 107, in _run_task_by_selected_method
    _run_raw_task(args, ti)
  File "/home/airflow/.local/lib/python3.7/site-packages/airflow/cli/commands/task_command.py", line 184, in _run_raw_task
    error_file=args.error_file,
  File "/home/airflow/.local/lib/python3.7/site-packages/airflow/utils/session.py", line 70, in wrapper
    return func(*args, session=session, **kwargs)
  File "/home/airflow/.local/lib/python3.7/site-packages/airflow/models/taskinstance.py", line 1329, in _run_raw_task
    self._execute_task_with_callbacks(context)
  File "/home/airflow/.local/lib/python3.7/site-packages/airflow/models/taskinstance.py", line 1455, in _execute_task_with_callbacks
    result = self._execute_task(context, self.task)
  File "/home/airflow/.local/lib/python3.7/site-packages/airflow/models/taskinstance.py", line 1511, in _execute_task
    result = execute_callable(context=context)
  File "/home/airflow/.local/lib/python3.7/site-packages/airflow/operators/python.py", line 174, in execute
    return_value = self.execute_callable()
  File "/home/airflow/.local/lib/python3.7/site-packages/airflow/operators/python.py", line 185, in execute_callable
    return self.python_callable(*self.op_args, **self.op_kwargs)
  File "/opt/airflow/dags/mydag.py", line 87, in _load_to_s3
    import reddit_data as reddit
  File "/opt/airflow/dags/reddit_data.py", line 9, in <module>
    import s3 as s3boto
  File "/opt/airflow/dags/s3.py", line 44, in <module>
    os.remove(filename)
FileNotFoundError: [Errno 2] No such file or directory: 'reddit_posts_2022-02-25.xlsx'
[2022-02-25 01:50:48,444] {local_task_job.py:154} INFO - Task exited with return code 1
[2022-02-25 01:50:48,549] {local_task_job.py:264} INFO - 0 downstream tasks scheduled from follow-on schedule check
