[2022-02-24 20:00:45,396] {taskinstance.py:1032} INFO - Dependencies all met for <TaskInstance: Project_Mapping.get_reddit_data scheduled__2022-02-24T02:00:00+00:00 [queued]>
[2022-02-24 20:00:45,469] {taskinstance.py:1032} INFO - Dependencies all met for <TaskInstance: Project_Mapping.get_reddit_data scheduled__2022-02-24T02:00:00+00:00 [queued]>
[2022-02-24 20:00:45,477] {taskinstance.py:1238} INFO - 
--------------------------------------------------------------------------------
[2022-02-24 20:00:45,481] {taskinstance.py:1239} INFO - Starting attempt 1 of 1
[2022-02-24 20:00:45,485] {taskinstance.py:1240} INFO - 
--------------------------------------------------------------------------------
[2022-02-24 20:00:45,605] {taskinstance.py:1259} INFO - Executing <Task(_PythonDecoratedOperator): get_reddit_data> on 2022-02-24 02:00:00+00:00
[2022-02-24 20:00:45,635] {standard_task_runner.py:52} INFO - Started process 575 to run task
[2022-02-24 20:00:45,653] {standard_task_runner.py:76} INFO - Running: ['***', 'tasks', 'run', 'Project_Mapping', 'get_reddit_data', 'scheduled__2022-02-24T02:00:00+00:00', '--job-id', '36', '--raw', '--subdir', 'DAGS_FOLDER/mydag.py', '--cfg-path', '/tmp/tmp0u_yhhmi', '--error-file', '/tmp/tmp9x32fks_']
[2022-02-24 20:00:45,661] {standard_task_runner.py:77} INFO - Job 36: Subtask get_reddit_data
[2022-02-24 20:00:46,267] {logging_mixin.py:109} INFO - Running <TaskInstance: Project_Mapping.get_reddit_data scheduled__2022-02-24T02:00:00+00:00 [running]> on host 717d92cd82bb
[2022-02-24 20:00:46,842] {taskinstance.py:1426} INFO - Exporting the following env vars:
AIRFLOW_CTX_DAG_OWNER=***
AIRFLOW_CTX_DAG_ID=Project_Mapping
AIRFLOW_CTX_TASK_ID=get_reddit_data
AIRFLOW_CTX_EXECUTION_DATE=2022-02-24T02:00:00+00:00
AIRFLOW_CTX_DAG_RUN_ID=scheduled__2022-02-24T02:00:00+00:00
[2022-02-24 20:12:11,330] {logging_mixin.py:109} INFO - Negative
[2022-02-24 21:00:02,795] {base_job.py:230} ERROR - LocalTaskJob heartbeat got an exception
Traceback (most recent call last):
  File "/home/airflow/.local/lib/python3.7/site-packages/sqlalchemy/engine/base.py", line 2336, in _wrap_pool_connect
    return fn()
  File "/home/airflow/.local/lib/python3.7/site-packages/sqlalchemy/pool/base.py", line 364, in connect
    return _ConnectionFairy._checkout(self)
  File "/home/airflow/.local/lib/python3.7/site-packages/sqlalchemy/pool/base.py", line 778, in _checkout
    fairy = _ConnectionRecord.checkout(pool)
  File "/home/airflow/.local/lib/python3.7/site-packages/sqlalchemy/pool/base.py", line 495, in checkout
    rec = pool._do_get()
  File "/home/airflow/.local/lib/python3.7/site-packages/sqlalchemy/pool/impl.py", line 241, in _do_get
    return self._create_connection()
  File "/home/airflow/.local/lib/python3.7/site-packages/sqlalchemy/pool/base.py", line 309, in _create_connection
    return _ConnectionRecord(self)
  File "/home/airflow/.local/lib/python3.7/site-packages/sqlalchemy/pool/base.py", line 440, in __init__
    self.__connect(first_connect_check=True)
  File "/home/airflow/.local/lib/python3.7/site-packages/sqlalchemy/pool/base.py", line 661, in __connect
    pool.logger.debug("Error on connect(): %s", e)
  File "/home/airflow/.local/lib/python3.7/site-packages/sqlalchemy/util/langhelpers.py", line 70, in __exit__
    with_traceback=exc_tb,
  File "/home/airflow/.local/lib/python3.7/site-packages/sqlalchemy/util/compat.py", line 182, in raise_
    raise exception
  File "/home/airflow/.local/lib/python3.7/site-packages/sqlalchemy/pool/base.py", line 656, in __connect
    connection = pool._invoke_creator(self)
  File "/home/airflow/.local/lib/python3.7/site-packages/sqlalchemy/engine/strategies.py", line 114, in connect
    return dialect.connect(*cargs, **cparams)
  File "/home/airflow/.local/lib/python3.7/site-packages/sqlalchemy/engine/default.py", line 508, in connect
    return self.dbapi.connect(*cargs, **cparams)
  File "/home/airflow/.local/lib/python3.7/site-packages/psycopg2/__init__.py", line 122, in connect
    conn = _connect(dsn, connection_factory=connection_factory, **kwasync)
psycopg2.OperationalError: could not translate host name "postgres" to address: Temporary failure in name resolution


The above exception was the direct cause of the following exception:

Traceback (most recent call last):
  File "/home/airflow/.local/lib/python3.7/site-packages/airflow/jobs/base_job.py", line 226, in heartbeat
    self.heartbeat_callback(session=session)
  File "/home/airflow/.local/lib/python3.7/site-packages/airflow/utils/session.py", line 67, in wrapper
    return func(*args, **kwargs)
  File "/home/airflow/.local/lib/python3.7/site-packages/airflow/jobs/local_task_job.py", line 184, in heartbeat_callback
    self.task_instance.refresh_from_db()
  File "/home/airflow/.local/lib/python3.7/site-packages/airflow/utils/session.py", line 70, in wrapper
    return func(*args, session=session, **kwargs)
  File "/home/airflow/.local/lib/python3.7/site-packages/airflow/models/taskinstance.py", line 728, in refresh_from_db
    ti = qry.first()
  File "/home/airflow/.local/lib/python3.7/site-packages/sqlalchemy/orm/query.py", line 3429, in first
    ret = list(self[0:1])
  File "/home/airflow/.local/lib/python3.7/site-packages/sqlalchemy/orm/query.py", line 3203, in __getitem__
    return list(res)
  File "/home/airflow/.local/lib/python3.7/site-packages/sqlalchemy/orm/query.py", line 3535, in __iter__
    return self._execute_and_instances(context)
  File "/home/airflow/.local/lib/python3.7/site-packages/sqlalchemy/orm/query.py", line 3557, in _execute_and_instances
    querycontext, self._connection_from_session, close_with_result=True
  File "/home/airflow/.local/lib/python3.7/site-packages/sqlalchemy/orm/query.py", line 3572, in _get_bind_args
    mapper=self._bind_mapper(), clause=querycontext.statement, **kw
  File "/home/airflow/.local/lib/python3.7/site-packages/sqlalchemy/orm/query.py", line 3550, in _connection_from_session
    conn = self.session.connection(**kw)
  File "/home/airflow/.local/lib/python3.7/site-packages/sqlalchemy/orm/session.py", line 1145, in connection
    execution_options=execution_options,
  File "/home/airflow/.local/lib/python3.7/site-packages/sqlalchemy/orm/session.py", line 1151, in _connection_for_bind
    engine, execution_options
  File "/home/airflow/.local/lib/python3.7/site-packages/sqlalchemy/orm/session.py", line 433, in _connection_for_bind
    conn = bind._contextual_connect()
  File "/home/airflow/.local/lib/python3.7/site-packages/sqlalchemy/engine/base.py", line 2302, in _contextual_connect
    self._wrap_pool_connect(self.pool.connect, None),
  File "/home/airflow/.local/lib/python3.7/site-packages/sqlalchemy/engine/base.py", line 2340, in _wrap_pool_connect
    e, dialect, self
  File "/home/airflow/.local/lib/python3.7/site-packages/sqlalchemy/engine/base.py", line 1584, in _handle_dbapi_exception_noconnection
    sqlalchemy_exception, with_traceback=exc_info[2], from_=e
  File "/home/airflow/.local/lib/python3.7/site-packages/sqlalchemy/util/compat.py", line 182, in raise_
    raise exception
  File "/home/airflow/.local/lib/python3.7/site-packages/sqlalchemy/engine/base.py", line 2336, in _wrap_pool_connect
    return fn()
  File "/home/airflow/.local/lib/python3.7/site-packages/sqlalchemy/pool/base.py", line 364, in connect
    return _ConnectionFairy._checkout(self)
  File "/home/airflow/.local/lib/python3.7/site-packages/sqlalchemy/pool/base.py", line 778, in _checkout
    fairy = _ConnectionRecord.checkout(pool)
  File "/home/airflow/.local/lib/python3.7/site-packages/sqlalchemy/pool/base.py", line 495, in checkout
    rec = pool._do_get()
  File "/home/airflow/.local/lib/python3.7/site-packages/sqlalchemy/pool/impl.py", line 241, in _do_get
    return self._create_connection()
  File "/home/airflow/.local/lib/python3.7/site-packages/sqlalchemy/pool/base.py", line 309, in _create_connection
    return _ConnectionRecord(self)
  File "/home/airflow/.local/lib/python3.7/site-packages/sqlalchemy/pool/base.py", line 440, in __init__
    self.__connect(first_connect_check=True)
  File "/home/airflow/.local/lib/python3.7/site-packages/sqlalchemy/pool/base.py", line 661, in __connect
    pool.logger.debug("Error on connect(): %s", e)
  File "/home/airflow/.local/lib/python3.7/site-packages/sqlalchemy/util/langhelpers.py", line 70, in __exit__
    with_traceback=exc_tb,
  File "/home/airflow/.local/lib/python3.7/site-packages/sqlalchemy/util/compat.py", line 182, in raise_
    raise exception
  File "/home/airflow/.local/lib/python3.7/site-packages/sqlalchemy/pool/base.py", line 656, in __connect
    connection = pool._invoke_creator(self)
  File "/home/airflow/.local/lib/python3.7/site-packages/sqlalchemy/engine/strategies.py", line 114, in connect
    return dialect.connect(*cargs, **cparams)
  File "/home/airflow/.local/lib/python3.7/site-packages/sqlalchemy/engine/default.py", line 508, in connect
    return self.dbapi.connect(*cargs, **cparams)
  File "/home/airflow/.local/lib/python3.7/site-packages/psycopg2/__init__.py", line 122, in connect
    conn = _connect(dsn, connection_factory=connection_factory, **kwasync)
sqlalchemy.exc.OperationalError: (psycopg2.OperationalError) could not translate host name "postgres" to address: Temporary failure in name resolution

(Background on this error at: http://sqlalche.me/e/13/e3q8)
[2022-02-24 21:02:22,322] {local_task_job.py:154} INFO - Task exited with return code Negsignal.SIGKILL
[2022-02-24 21:03:37,401] {taskinstance.py:1277} INFO - Marking task as FAILED. dag_id=Project_Mapping, task_id=get_reddit_data, execution_date=20220224T020000, start_date=20220224T200045, end_date=20220224T210254
[2022-02-24 21:05:42,833] {dagrun.py:628} WARNING - Failed to get task '<TaskInstance: Project_Mapping.loading_data scheduled__2022-02-24T02:00:00+00:00 [None]>' for dag 'Project_Mapping'. Marking it as removed.
[2022-02-24 21:06:39,301] {local_task_job.py:264} INFO - 0 downstream tasks scheduled from follow-on schedule check
