[2022-02-24 18:29:37,164] {taskinstance.py:1032} INFO - Dependencies all met for <TaskInstance: Project_Mapping.get_reddit_data scheduled__2022-02-23T00:00:00+00:00 [queued]>
[2022-02-24 18:29:37,271] {taskinstance.py:1032} INFO - Dependencies all met for <TaskInstance: Project_Mapping.get_reddit_data scheduled__2022-02-23T00:00:00+00:00 [queued]>
[2022-02-24 18:29:37,277] {taskinstance.py:1238} INFO - 
--------------------------------------------------------------------------------
[2022-02-24 18:29:37,281] {taskinstance.py:1239} INFO - Starting attempt 1 of 1
[2022-02-24 18:29:37,284] {taskinstance.py:1240} INFO - 
--------------------------------------------------------------------------------
[2022-02-24 18:29:37,393] {taskinstance.py:1259} INFO - Executing <Task(_PythonDecoratedOperator): get_reddit_data> on 2022-02-23 00:00:00+00:00
[2022-02-24 18:29:37,410] {standard_task_runner.py:52} INFO - Started process 1001 to run task
[2022-02-24 18:29:37,451] {standard_task_runner.py:76} INFO - Running: ['***', 'tasks', 'run', 'Project_Mapping', 'get_reddit_data', 'scheduled__2022-02-23T00:00:00+00:00', '--job-id', '31', '--raw', '--subdir', 'DAGS_FOLDER/mydag.py', '--cfg-path', '/tmp/tmpztsv_bcw', '--error-file', '/tmp/tmpfho5rv6s']
[2022-02-24 18:29:37,456] {standard_task_runner.py:77} INFO - Job 31: Subtask get_reddit_data
[2022-02-24 18:29:37,872] {logging_mixin.py:109} INFO - Running <TaskInstance: Project_Mapping.get_reddit_data scheduled__2022-02-23T00:00:00+00:00 [running]> on host 717d92cd82bb
[2022-02-24 18:29:38,320] {taskinstance.py:1426} INFO - Exporting the following env vars:
AIRFLOW_CTX_DAG_OWNER=***
AIRFLOW_CTX_DAG_ID=Project_Mapping
AIRFLOW_CTX_TASK_ID=get_reddit_data
AIRFLOW_CTX_EXECUTION_DATE=2022-02-23T00:00:00+00:00
AIRFLOW_CTX_DAG_RUN_ID=scheduled__2022-02-23T00:00:00+00:00
[2022-02-24 18:30:23,631] {logging_mixin.py:109} INFO - Negative
[2022-02-24 18:30:23,636] {taskinstance.py:1700} ERROR - Task failed with exception
Traceback (most recent call last):
  File "/home/airflow/.local/lib/python3.7/site-packages/airflow/models/taskinstance.py", line 1329, in _run_raw_task
    self._execute_task_with_callbacks(context)
  File "/home/airflow/.local/lib/python3.7/site-packages/airflow/models/taskinstance.py", line 1455, in _execute_task_with_callbacks
    result = self._execute_task(context, self.task)
  File "/home/airflow/.local/lib/python3.7/site-packages/airflow/models/taskinstance.py", line 1511, in _execute_task
    result = execute_callable(context=context)
  File "/home/airflow/.local/lib/python3.7/site-packages/airflow/decorators/base.py", line 134, in execute
    return_value = super().execute(context)
  File "/home/airflow/.local/lib/python3.7/site-packages/airflow/operators/python.py", line 174, in execute
    return_value = self.execute_callable()
  File "/home/airflow/.local/lib/python3.7/site-packages/airflow/operators/python.py", line 185, in execute_callable
    return self.python_callable(*self.op_args, **self.op_kwargs)
  File "/opt/airflow/dags/mydag.py", line 38, in get_reddit_data
    redditdata = train.Reddit()
AttributeError: module 'train_data' has no attribute 'Reddit'
[2022-02-24 18:30:23,698] {taskinstance.py:1277} INFO - Marking task as FAILED. dag_id=Project_Mapping, task_id=get_reddit_data, execution_date=20220223T000000, start_date=20220224T182937, end_date=20220224T183023
[2022-02-24 18:30:23,780] {standard_task_runner.py:92} ERROR - Failed to execute job 31 for task get_reddit_data
Traceback (most recent call last):
  File "/home/airflow/.local/lib/python3.7/site-packages/airflow/task/task_runner/standard_task_runner.py", line 85, in _start_by_fork
    args.func(args, dag=self.dag)
  File "/home/airflow/.local/lib/python3.7/site-packages/airflow/cli/cli_parser.py", line 48, in command
    return func(*args, **kwargs)
  File "/home/airflow/.local/lib/python3.7/site-packages/airflow/utils/cli.py", line 92, in wrapper
    return f(*args, **kwargs)
  File "/home/airflow/.local/lib/python3.7/site-packages/airflow/cli/commands/task_command.py", line 298, in task_run
    _run_task_by_selected_method(args, dag, ti)
  File "/home/airflow/.local/lib/python3.7/site-packages/airflow/cli/commands/task_command.py", line 107, in _run_task_by_selected_method
    _run_raw_task(args, ti)
  File "/home/airflow/.local/lib/python3.7/site-packages/airflow/cli/commands/task_command.py", line 184, in _run_raw_task
    error_file=args.error_file,
  File "/home/airflow/.local/lib/python3.7/site-packages/airflow/utils/session.py", line 70, in wrapper
    return func(*args, session=session, **kwargs)
  File "/home/airflow/.local/lib/python3.7/site-packages/airflow/models/taskinstance.py", line 1329, in _run_raw_task
    self._execute_task_with_callbacks(context)
  File "/home/airflow/.local/lib/python3.7/site-packages/airflow/models/taskinstance.py", line 1455, in _execute_task_with_callbacks
    result = self._execute_task(context, self.task)
  File "/home/airflow/.local/lib/python3.7/site-packages/airflow/models/taskinstance.py", line 1511, in _execute_task
    result = execute_callable(context=context)
  File "/home/airflow/.local/lib/python3.7/site-packages/airflow/decorators/base.py", line 134, in execute
    return_value = super().execute(context)
  File "/home/airflow/.local/lib/python3.7/site-packages/airflow/operators/python.py", line 174, in execute
    return_value = self.execute_callable()
  File "/home/airflow/.local/lib/python3.7/site-packages/airflow/operators/python.py", line 185, in execute_callable
    return self.python_callable(*self.op_args, **self.op_kwargs)
  File "/opt/airflow/dags/mydag.py", line 38, in get_reddit_data
    redditdata = train.Reddit()
AttributeError: module 'train_data' has no attribute 'Reddit'
[2022-02-24 18:30:23,895] {local_task_job.py:154} INFO - Task exited with return code 1
[2022-02-24 18:30:24,057] {local_task_job.py:264} INFO - 0 downstream tasks scheduled from follow-on schedule check
